[2022-05-29 08:27:09,815] {taskinstance.py:1160} INFO - Dependencies all met for <TaskInstance: Etl.get_data scheduled__2022-05-27T00:00:00+00:00 [queued]>
[2022-05-29 08:27:09,822] {taskinstance.py:1160} INFO - Dependencies all met for <TaskInstance: Etl.get_data scheduled__2022-05-27T00:00:00+00:00 [queued]>
[2022-05-29 08:27:09,822] {taskinstance.py:1357} INFO - 
--------------------------------------------------------------------------------
[2022-05-29 08:27:09,822] {taskinstance.py:1358} INFO - Starting attempt 1 of 1
[2022-05-29 08:27:09,822] {taskinstance.py:1359} INFO - 
--------------------------------------------------------------------------------
[2022-05-29 08:27:09,830] {taskinstance.py:1378} INFO - Executing <Task(_PythonDecoratedOperator): get_data> on 2022-05-27 00:00:00+00:00
[2022-05-29 08:27:09,832] {standard_task_runner.py:52} INFO - Started process 66 to run task
[2022-05-29 08:27:09,834] {standard_task_runner.py:79} INFO - Running: ['***', 'tasks', 'run', 'Etl', 'get_data', 'scheduled__2022-05-27T00:00:00+00:00', '--job-id', '42', '--raw', '--subdir', 'DAGS_FOLDER/my_first_dag.py', '--cfg-path', '/tmp/tmpmwbezrdb', '--error-file', '/tmp/tmp9t10rzc_']
[2022-05-29 08:27:09,834] {standard_task_runner.py:80} INFO - Job 42: Subtask get_data
[2022-05-29 08:27:09,869] {task_command.py:370} INFO - Running <TaskInstance: Etl.get_data scheduled__2022-05-27T00:00:00+00:00 [running]> on host b7bcf2b221fa
[2022-05-29 08:27:09,917] {taskinstance.py:1572} INFO - Exporting the following env vars:
AIRFLOW_CTX_DAG_OWNER=***
AIRFLOW_CTX_DAG_ID=Etl
AIRFLOW_CTX_TASK_ID=get_data
AIRFLOW_CTX_EXECUTION_DATE=2022-05-27T00:00:00+00:00
AIRFLOW_CTX_TRY_NUMBER=1
AIRFLOW_CTX_DAG_RUN_ID=scheduled__2022-05-27T00:00:00+00:00
[2022-05-29 08:27:10,126] {base.py:68} INFO - Using connection ID 'tutorial_pg_conn' for task execution.
[2022-05-29 08:27:10,139] {taskinstance.py:1890} ERROR - Task failed with exception
Traceback (most recent call last):
  File "/home/airflow/.local/lib/python3.7/site-packages/airflow/decorators/base.py", line 179, in execute
    return_value = super().execute(context)
  File "/home/airflow/.local/lib/python3.7/site-packages/airflow/operators/python.py", line 171, in execute
    return_value = self.execute_callable()
  File "/home/airflow/.local/lib/python3.7/site-packages/airflow/operators/python.py", line 189, in execute_callable
    return self.python_callable(*self.op_args, **self.op_kwargs)
  File "/opt/airflow/dags/my_first_dag.py", line 64, in get_data
    file,
psycopg2.errors.UniqueViolation: duplicate key value violates unique constraint "employees_temp_pkey"
DETAIL:  Key ("Serial Number")=(2) already exists.
CONTEXT:  COPY employees_temp, line 2

[2022-05-29 08:27:10,146] {taskinstance.py:1401} INFO - Marking task as FAILED. dag_id=Etl, task_id=get_data, execution_date=20220527T000000, start_date=20220529T082709, end_date=20220529T082710
[2022-05-29 08:27:10,157] {standard_task_runner.py:97} ERROR - Failed to execute job 42 for task get_data (duplicate key value violates unique constraint "employees_temp_pkey"
DETAIL:  Key ("Serial Number")=(2) already exists.
CONTEXT:  COPY employees_temp, line 2
; 66)
[2022-05-29 08:27:10,166] {local_task_job.py:156} INFO - Task exited with return code 1
[2022-05-29 08:27:10,198] {local_task_job.py:273} INFO - 0 downstream tasks scheduled from follow-on schedule check
